Exception:
Traceback (most recent call last):
  File "/usr/lib/python3.6/shutil.py", line 544, in move
    os.rename(src, real_dst)
FileNotFoundError: [Errno 2] No such file or directory: '/work/tbury/.local/lib/python3.6/site-packages/pytz-2019.3.dist-info/RECORD.pip' -> '/work/tbury/.local/lib/python3.6/site-packages/pytz-2019.3.dist-info/RECORD'

During handling of the above exception, another exception occurred:

Traceback (most recent call last):
  File "/usr/lib/python3/dist-packages/pip/basecommand.py", line 215, in main
    status = self.run(options, args)
  File "/usr/lib/python3/dist-packages/pip/commands/install.py", line 360, in run
    prefix=options.prefix_path,
  File "/usr/lib/python3/dist-packages/pip/req/req_set.py", line 784, in install
    **kwargs
  File "/usr/lib/python3/dist-packages/pip/req/req_install.py", line 851, in install
    self.move_wheel_files(self.source_dir, root=root, prefix=prefix)
  File "/usr/lib/python3/dist-packages/pip/req/req_install.py", line 1064, in move_wheel_files
    isolated=self.isolated,
  File "/usr/lib/python3/dist-packages/pip/wheel.py", line 527, in move_wheel_files
    shutil.move(temp_record, record)
  File "/usr/lib/python3.6/shutil.py", line 558, in move
    copy_function(src, real_dst)
  File "/usr/lib/python3.6/shutil.py", line 257, in copy2
    copyfile(src, dst, follow_symlinks=follow_symlinks)
  File "/usr/lib/python3.6/shutil.py", line 120, in copyfile
    with open(src, 'rb') as fsrc:
FileNotFoundError: [Errno 2] No such file or directory: '/work/tbury/.local/lib/python3.6/site-packages/pytz-2019.3.dist-info/RECORD.pip'
Traceback (most recent call last):
  File "../../sim_stat_hag.py", line 25, in <module>
    import seaborn as sns
ModuleNotFoundError: No module named 'seaborn'

real	0m1.031s
user	0m0.553s
sys	0m0.159s
